Workbook

Sheet Curve
A1: 1_Case Temp | B1: 5_Case Temp | C1: 1_Opr_Wavelength | D1: 5_Opr_Wavelength | E1: Max_Case Temp | F1: 1_Max_Wavelength | G1: 5_Max_Wavelength | H1: [CH1_DDMI_Opr_Bias] | I1: [CH5_DDMI_Opr_Bias] | J1: [CH1_DDMI_Max_Bias] | K1: [CH1_Opr_TxP] | L1: [CH5_Opr_TxP] | M1: [CH1_Max_TxP] | N1: [CH5_Max_TxP] | O1: [1_Opr_dW/dT] | P1: [5_Opr_dW/dT] | Q1: 1_Max_dW/dT] | R1: [5_Max_dW/dT] | S1: Max | T1: Min
A2: ='1_Operational'!C2 -> 0.2 | B2: ='5_Operational'!C2 -> 0.2 | C2: ='1_Operational'!D2 -> 1307.305 | D2: ='5_Operational'!D2 -> 1307.389 | E2: ='1_Maximum'!C2 -> 69.76 | F2: ='1_Maximum'!D2 -> 1314.858 | G2: ='5_Maximum'!D2 -> 1314.647 | H2: ='1_Operational'!F2 -> 271.12 | I2: ='5_Operational'!J2 -> 352.24 | J2: ='1_Maximum'!F2:F95 -> 399 | K2: ='1_Operational'!E2 -> 3.46 | L2: ='5_Operational'!E2 -> -0.51 | M2: ='1_Maximum'!E2 -> -2.15 | N2: ='5_Maximum'!E2 -> 0.32 | O2: ='1_Operational'!N2 -> 0.06 | P2: ='5_Operational'!N2 -> 0.07 | Q2: ='1_Maximum'!N2 -> 0.08 | R2: ='5_Maximum'!N2 -> 0.1 | S2: 0.2 | T2: 0
A3: ='1_Operational'!C3 -> 0.96 | B3: ='5_Operational'!C3 -> 0.96 | C3: ='1_Operational'!D3 -> 1307.352 | D3: ='5_Operational'!D3 -> 1307.443 | E3: ='1_Maximum'!C3 -> 69.01 | F3: ='1_Maximum'!D3 -> 1314.784 | G3: ='5_Maximum'!D3 -> 1314.586 | H3: ='1_Operational'!F3 -> 269.6 | I3: ='5_Operational'!J3 -> 351.84 | J3: ='1_Maximum'!F3:F96 -> 399 | K3: ='1_Operational'!E3 -> 3.51 | L3: ='5_Operational'!E3 -> -0.52 | M3: ='1_Maximum'!E3 -> -1.9 | N3: ='5_Maximum'!E3 -> 0.51 | O3: ='1_Operational'!N3 -> 0.06 | P3: ='5_Operational'!N3 -> 0.07 | Q3: ='1_Maximum'!N3 -> 0.1 | R3: ='5_Maximum'!N3 -> 0.08 | S3: 0.2 | T3: 0
A4: ='1_Operational'!C4 -> 1.7 | B4: ='5_Operational'!C4 -> 1.7 | C4: ='1_Operational'!D4 -> 1307.402 | D4: ='5_Operational'!D4 -> 1307.497 | E4: ='1_Maximum'!C4 -> 68.26 | F4: ='1_Maximum'!D4 -> 1314.718 | G4: ='5_Maximum'!D4 -> 1314.516 | H4: ='1_Operational'!F4 -> 267.84 | I4: ='5_Operational'!J4 -> 351.28 | J4: ='1_Maximum'!F4:F97 -> 399 | K4: ='1_Operational'!E4 -> 3.55 | L4: ='5_Operational'!E4 -> -0.6 | M4: ='1_Maximum'!E4 -> -1.7 | N4: ='5_Maximum'!E4 -> 0.7 | O4: ='1_Operational'!N4 -> 0.07 | P4: ='5_Operational'!N4 -> 0.07 | Q4: ='1_Maximum'!N4 -> 0.09 | R4: ='5_Maximum'!N4 -> 0.09 | S4: 0.2 | T4: 0
A5: ='1_Operational'!C5 -> 2.43 | B5: ='5_Operational'!C5 -> 2.43 | C5: ='1_Operational'!D5 -> 1307.446 | D5: ='5_Operational'!D5 -> 1307.557 | E5: ='1_Maximum'!C5 -> 67.51 | F5: ='1_Maximum'!D5 -> 1314.648 | G5: ='5_Maximum'!D5 -> 1314.448 | H5: ='1_Operational'!F5 -> 265.8 | I5: ='5_Operational'!J5 -> 350.48 | J5: ='1_Maximum'!F5:F98 -> 399 | K5: ='1_Operational'!E5 -> 3.52 | L5: ='5_Operational'!E5 -> -0.54 | M5: ='1_Maximum'!E5 -> -1.47 | N5: ='5_Maximum'!E5 -> 1.02 | O5: ='1_Operational'!N5 -> 0.06 | P5: ='5_Operational'!N5 -> 0.08 | Q5: ='1_Maximum'!N5 -> 0.09 | R5: ='5_Maximum'!N5 -> 0.09 | S5: 0.2 | T5: 0
A6: ='1_Operational'!C6 -> 3.16 | B6: ='5_Operational'!C6 -> 3.16 | C6: ='1_Operational'!D6 -> 1307.502 | D6: ='5_Operational'!D6 -> 1307.607 | E6: ='1_Maximum'!C6 -> 66.78 | F6: ='1_Maximum'!D6 -> 1314.579 | G6: ='5_Maximum'!D6 -> 1314.378 | H6: ='1_Operational'!F6 -> 264 | I6: ='5_Operational'!J6 -> 349.64 | J6: ='1_Maximum'!F6:F99 -> 399 | K6: ='1_Operational'!E6 -> 3.51 | L6: ='5_Operational'!E6 -> -0.54 | M6: ='1_Maximum'!E6 -> -1.23 | N6: ='5_Maximum'!E6 -> 1.17 | O6: ='1_Operational'!N6 -> 0.08 | P6: ='5_Operational'!N6 -> 0.07 | Q6: ='1_Maximum'!N6 -> 0.09 | R6: ='5_Maximum'!N6 -> 0.1 | S6: 0.2 | T6: 0
A7: ='1_Operational'!C7 -> 3.91 | B7: ='5_Operational'!C7 -> 3.91 | C7: ='1_Operational'!D7 -> 1307.554 | D7: ='5_Operational'!D7 -> 1307.663 | E7: ='1_Maximum'!C7 -> 66.04 | F7: ='1_Maximum'!D7 -> 1314.515 | G7: ='5_Maximum'!D7 -> 1314.301 | H7: ='1_Operational'!F7 -> 261.8 | I7: ='5_Operational'!J7 -> 348.64 | J7: ='1_Maximum'!F7:F100 -> 399 | K7: ='1_Operational'!E7 -> 3.56 | L7: ='5_Operational'!E7 -> -0.46 | M7: ='1_Maximum'!E7 -> -0.98 | N7: ='5_Maximum'!E7 -> 1.69 | O7: ='1_Operational'!N7 -> 0.07 | P7: ='5_Operational'!N7 -> 0.07 | Q7: ='1_Maximum'!N7 -> 0.09 | R7: ='5_Maximum'!N7 -> 0.1 | S7: 0.2 | T7: 0
A8: ='1_Operational'!C8 -> 4.64 | B8: ='5_Operational'!C8 -> 4.64 | C8: ='1_Operational'!D8 -> 1307.607 | D8: ='5_Operational'!D8 -> 1307.719 | E8: ='1_Maximum'!C8 -> 65.31 | F8: ='1_Maximum'!D8 -> 1314.436 | G8: ='5_Maximum'!D8 -> 1314.238 | H8: ='1_Operational'!F8 -> 259.72 | I8: ='5_Operational'!J8 -> 347.64 | J8: ='1_Maximum'!F8:F101 -> 399 | K8: ='1_Operational'!E8 -> 3.57 | L8: ='5_Operational'!E8 -> -0.52 | M8: ='1_Maximum'!E8 -> -0.66 | N8: ='5_Maximum'!E8 -> 1.97 | O8: ='1_Operational'!N8 -> 0.07 | P8: ='5_Operational'!N8 -> 0.08 | Q8: ='1_Maximum'!N8 -> 0.11 | R8: ='5_Maximum'!N8 -> 0.09 | S8: 0.2 | T8: 0
A9: ='1_Operational'!C9 -> 5.39 | B9: ='5_Operational'!C9 -> 5.39 | C9: ='1_Operational'!D9 -> 1307.66 | D9: ='5_Operational'!D9 -> 1307.775 | E9: ='1_Maximum'!C9 -> 64.57 | F9: ='1_Maximum'!D9 -> 1314.364 | G9: ='5_Maximum'!D9 -> 1314.166 | H9: ='1_Operational'!F9 -> 257.64 | I9: ='5_Operational'!J9 -> 346.6 | J9: ='1_Maximum'!F9:F102 -> 399 | K9: ='1_Operational'!E9 -> 3.57 | L9: ='5_Operational'!E9 -> -0.43 | M9: ='1_Maximum'!E9 -> -0.51 | N9: ='5_Maximum'!E9 -> 2.26 | O9: ='1_Operational'!N9 -> 0.07 | P9: ='5_Operational'!N9 -> 0.07 | Q9: ='1_Maximum'!N9 -> 0.1 | R9: ='5_Maximum'!N9 -> 0.1 | S9: 0.2 | T9: 0
A10: ='1_Operational'!C10 -> 6.13 | B10: ='5_Operational'!C10 -> 6.13 | C10: ='1_Operational'!D10 -> 1307.713 | D10: ='5_Operational'!D10 -> 1307.832 | E10: ='1_Maximum'!C10 -> 63.84 | F10: ='1_Maximum'!D10 -> 1314.3 | G10: ='5_Maximum'!D10 -> 1314.088 | H10: ='1_Operational'!F10 -> 255.4 | I10: ='5_Operational'!J10 -> 345.36 | J10: ='1_Maximum'!F10:F103 -> 399 | K10: ='1_Operational'!E10 -> 3.58 | L10: ='5_Operational'!E10 -> -0.34 | M10: ='1_Maximum'!E10 -> -0.35 | N10: ='5_Maximum'!E10 -> 2.68 | O10: ='1_Operational'!N10 -> 0.07 | P10: ='5_Operational'!N10 -> 0.08 | Q10: ='1_Maximum'!N10 -> 0.09 | R10: ='5_Maximum'!N10 -> 0.11 | S10: 0.2 | T10: 0
A11: ='1_Operational'!C11 -> 6.87 | B11: ='5_Operational'!C11 -> 6.87 | C11: ='1_Operational'!D11 -> 1307.768 | D11: ='5_Operational'!D11 -> 1307.891 | E11: ='1_Maximum'!C11 -> 63.09 | F11: ='1_Maximum'!D11 -> 1314.221 | G11: ='5_Maximum'!D11 -> 1314.023 | H11: ='1_Operational'!F11 -> 253.48 | I11: ='5_Operational'!J11 -> 344.08 | J11: ='1_Maximum'!F11:F104 -> 399 | K11: ='1_Operational'!E11 -> 3.58 | L11: ='5_Operational'!E11 -> -0.27 | M11: ='1_Maximum'!E11 -> -0.1 | N11: ='5_Maximum'!E11 -> 2.81 | O11: ='1_Operational'!N11 -> 0.07 | P11: ='5_Operational'!N11 -> 0.08 | Q11: ='1_Maximum'!N11 -> 0.11 | R11: ='5_Maximum'!N11 -> 0.09 | S11: 0.2 | T11: 0
A12: ='1_Operational'!C12 -> 7.63 | B12: ='5_Operational'!C12 -> 7.63 | C12: ='1_Operational'!D12 -> 1307.816 | D12: ='5_Operational'!D12 -> 1307.954 | E12: ='1_Maximum'!C12 -> 62.37 | F12: ='1_Maximum'!D12 -> 1314.151 | G12: ='5_Maximum'!D12 -> 1313.953 | H12: ='1_Operational'!F12 -> 251.36 | I12: ='5_Operational'!J12 -> 342.72 | J12: ='1_Maximum'!F12:F105 -> 399 | K12: ='1_Operational'!E12 -> 3.65 | L12: ='5_Operational'!E12 -> -0.31 | M12: ='1_Maximum'!E12 -> 0.13 | N12: ='5_Maximum'!E12 -> 3.15 | O12: ='1_Operational'!N12 -> 0.06 | P12: ='5_Operational'!N12 -> 0.08 | Q12: ='1_Maximum'!N12 -> 0.1 | R12: ='5_Maximum'!N12 -> 0.1 | S12: 0.2 | T12: 0
A13: ='1_Operational'!C13 -> 8.36 | B13: ='5_Operational'!C13 -> 8.36 | C13: ='1_Operational'!D13 -> 1307.873 | D13: ='5_Operational'!D13 -> 1308.013 | E13: ='1_Maximum'!C13 -> 61.62 | F13: ='1_Maximum'!D13 -> 1314.077 | G13: ='5_Maximum'!D13 -> 1313.881 | H13: ='1_Operational'!F13 -> 249.72 | I13: ='5_Operational'!J13 -> 341.36 | J13: ='1_Maximum'!F13:F106 -> 399 | K13: ='1_Operational'!E13 -> 3.64 | L13: ='5_Operational'!E13 -> -0.33 | M13: ='1_Maximum'!E13 -> 0.31 | N13: ='5_Maximum'!E13 -> 3.62 | O13: ='1_Operational'!N13 -> 0.08 | P13: ='5_Operational'!N13 -> 0.08 | Q13: ='1_Maximum'!N13 -> 0.1 | R13: ='5_Maximum'!N13 -> 0.1 | S13: 0.2 | T13: 0
... A95: ='1_Operational'!C95 -> 69.34 | B95: ='5_Operational'!C95 -> 69.34 | C95: ='1_Operational'!D95 -> 1314.287 | D95: ='5_Operational'!D95 -> 1314.099 | E95: ='1_Maximum'!C95 -> 0.54 | F95: ='1_Maximum'!D95 -> 1308.216 | G95: ='5_Maximum'!D95 -> 1308.013 | H95: ='1_Operational'!F95 -> 399 | I95: ='5_Operational'!J95 -> 399 | J95: ='1_Maximum'!F95:F188 -> 399 | K95: ='1_Operational'!E95 -> -0.36 | L95: ='5_Operational'!E95 -> -2.21 | M95: ='1_Maximum'!E95 -> 7.24 | N95: ='5_Maximum'!E95 -> 9.31 | O95: ='1_Operational'!N95 -> 0.11 | P95: ='5_Operational'!N95 -> 0.11 | Q95: ='1_Maximum'!N95 -> 0.1 | R95: ='5_Maximum'!N95 -> 0.08 | S95: 0.2 | T95: 0
A96: ='1_Operational'!C96 -> 69.97 | B96: ='5_Operational'!C96 -> 69.97 | C96: ='1_Operational'!D96 -> 1314.367 | D96: ='5_Operational'!D96 -> 1314.163 | H96: ='1_Operational'!F96 -> 399 | I96: ='5_Operational'!J96 -> 399 | J96: ='1_Maximum'!F96:F189 -> 0 | K96: ='1_Operational'!E96 -> -0.53 | L96: ='5_Operational'!E96 -> -2.34 | M96: ='1_Maximum'!E96 -> 0 | N96: ='5_Maximum'!E96 -> 0 | O96: ='1_Operational'!N96 -> 0.13 | P96: ='5_Operational'!N96 -> 0.1 | Q96: ='1_Maximum'!N96 -> 0 | R96: ='5_Maximum'!N96 -> 0 | S96: 0.2 | T96: 0

Sheet 1_Operational
A1: [CHNumber] | B1: [Times] | C1: [Case_Temp] | D1: [Wavelength] | E1: [TXP] | F1: [CH1_DDMI_Bias] | G1: [CH2_DDMI_Bias] | H1: [CH3_DDMI_Bias] | I1: [CH4_DDMI_Bias] | J1: [CH5_DDMI_Bias] | K1: [CH6_DDMI_Bias] | L1: [CH7_DDMI_Bias] | M1: [CH8_DDMI_Bias] | N1: [dW/dT] | O1: [Peak_WL_Jump_Max] | P1: [Peak_WL_Jump_Min] | Q1: [Peak_WL_Jump_Avg] | R1: [CH_Pass_Fail] | S1: [FailureCodeID] | T1: [ErrorMessage]
A2: =IF(ROWS($2:2)>COUNTIF(Operational_RawData!$A:$A,"1_Operational"),"",INDEX(Operational_RawData!A:A,MATCH("1_Operational",Operational_RawData!$A:$A,0)+ROWS($2:2)-1)) -> 1_Operational | B2: =IF(ROWS($2:2)>COUNTIF(Operational_RawData!$A:$A,"1_Operational"),"",INDEX(Operational_RawData!B:B,MATCH("1_Operational",Operational_RawData!$A:$A,0)+ROWS($2:2)-1)) -> 144406.82 | C2: =IF(ROWS($2:2)>COUNTIF(Operational_RawData!$A:$A,"1_Operational"),"",INDEX(Operational_RawData!C:C,MATCH("1_Operational",Operational_RawData!$A:$A,0)+ROWS($2:2)-1)) -> 0.2 | D2: =IF(ROWS($2:2)>COUNTIF(Operational_RawData!$A:$A,"1_Operational"),"",INDEX(Operational_RawData!D:D,MATCH("1_Operational",Operational_RawData!$A:$A,0)+ROWS($2:2)-1)) -> 1307.305 | E2: =IF(ROWS($2:2)>COUNTIF(Operational_RawData!$A:$A,"1_Operational"),"",INDEX(Operational_RawData!E:E,MATCH("1_Operational",Operational_RawData!$A:$A,0)+ROWS($2:2)-1)) -> 3.46 | F2: =IF(ROWS($2:2)>COUNTIF(Operational_RawData!$A:$A,"1_Operational"),"",INDEX(Operational_RawData!F:F,MATCH("1_Operational",Operational_RawData!$A:$A,0)+ROWS($2:2)-1)) -> 271.12 | G2: =IF(ROWS($2:2)>COUNTIF(Operational_RawData!$A:$A,"1_Operational"),"",INDEX(Operational_RawData!G:G,MATCH("1_Operational",Operational_RawData!$A:$A,0)+ROWS($2:2)-1)) -> 271.12 | H2: =IF(ROWS($2:2)>COUNTIF(Operational_RawData!$A:$A,"1_Operational"),"",INDEX(Operational_RawData!H:H,MATCH("1_Operational",Operational_RawData!$A:$A,0)+ROWS($2:2)-1)) -> 271.12 | I2: =IF(ROWS($2:2)>COUNTIF(Operational_RawData!$A:$A,"1_Operational"),"",INDEX(Operational_RawData!I:I,MATCH("1_Operational",Operational_RawData!$A:$A,0)+ROWS($2:2)-1)) -> 271.12 | J2: =IF(ROWS($2:2)>COUNTIF(Operational_RawData!$A:$A,"1_Operational"),"",INDEX(Operational_RawData!J:J,MATCH("1_Operational",Operational_RawData!$A:$A,0)+ROWS($2:2)-1)) -> 352.24 | K2: =IF(ROWS($2:2)>COUNTIF(Operational_RawData!$A:$A,"1_Operational"),"",INDEX(Operational_RawData!K:K,MATCH("1_Operational",Operational_RawData!$A:$A,0)+ROWS($2:2)-1)) -> 352.24 | L2: =IF(ROWS($2:2)>COUNTIF(Operational_RawData!$A:$A,"1_Operational"),"",INDEX(Operational_RawData!L:L,MATCH("1_Operational",Operational_RawData!$A:$A,0)+ROWS($2:2)-1)) -> 352.24 | M2: =IF(ROWS($2:2)>COUNTIF(Operational_RawData!$A:$A,"1_Operational"),"",INDEX(Operational_RawData!M:M,MATCH("1_Operational",Operational_RawData!$A:$A,0)+ROWS($2:2)-1)) -> 352.24 | N2: =IF(ROWS($2:2)>COUNTIF(Operational_RawData!$A:$A,"1_Operational"),"",INDEX(Operational_RawData!N:N,MATCH("1_Operational",Operational_RawData!$A:$A,0)+ROWS($2:2)-1)) -> 0.06 | O2: =IF(ROWS($2:2)>COUNTIF(Operational_RawData!$A:$A,"1_Operational"),"",INDEX(Operational_RawData!O:O,MATCH("1_Operational",Operational_RawData!$A:$A,0)+ROWS($2:2)-1)) -> 0.19 | P2: =IF(ROWS($2:2)>COUNTIF(Operational_RawData!$A:$A,"1_Operational"),"",INDEX(Operational_RawData!P:P,MATCH("1_Operational",Operational_RawData!$A:$A,0)+ROWS($2:2)-1)) -> 0.06 | Q2: =IF(ROWS($2:2)>COUNTIF(Operational_RawData!$A:$A,"1_Operational"),"",INDEX(Operational_RawData!Q:Q,MATCH("1_Operational",Operational_RawData!$A:$A,0)+ROWS($2:2)-1)) -> 0.1 | R2: =IF(ROWS($2:2)>COUNTIF(Operational_RawData!$A:$A,"1_Operational"),"",INDEX(Operational_RawData!R:R,MATCH("1_Operational",Operational_RawData!$A:$A,0)+ROWS($2:2)-1)) -> Pass | S2: =IF(ROWS($2:2)>COUNTIF(Operational_RawData!$A:$A,"1_Operational"),"",INDEX(Operational_RawData!S:S,MATCH("1_Operational",Operational_RawData!$A:$A,0)+ROWS($2:2)-1)) -> 0 | T2: =IF(ROWS($2:2)>COUNTIF(Operational_RawData!$A:$A,"1_Operational"),"",INDEX(Operational_RawData!T:T,MATCH("1_Operational",Operational_RawData!$A:$A,0)+ROWS($2:2)-1)) -> 0
A3: =IF(ROWS($2:3)>COUNTIF(Operational_RawData!$A:$A,"1_Operational"),"",INDEX(Operational_RawData!A:A,MATCH("1_Operational",Operational_RawData!$A:$A,0)+ROWS($2:3)-1)) -> 1_Operational | B3: =IF(ROWS($2:3)>COUNTIF(Operational_RawData!$A:$A,"1_Operational"),"",INDEX(Operational_RawData!B:B,MATCH("1_Operational",Operational_RawData!$A:$A,0)+ROWS($2:3)-1)) -> 144411.82 | C3: =IF(ROWS($2:3)>COUNTIF(Operational_RawData!$A:$A,"1_Operational"),"",INDEX(Operational_RawData!C:C,MATCH("1_Operational",Operational_RawData!$A:$A,0)+ROWS($2:3)-1)) -> 0.96 | D3: =IF(ROWS($2:3)>COUNTIF(Operational_RawData!$A:$A,"1_Operational"),"",INDEX(Operational_RawData!D:D,MATCH("1_Operational",Operational_RawData!$A:$A,0)+ROWS($2:3)-1)) -> 1307.352 | E3: =IF(ROWS($2:3)>COUNTIF(Operational_RawData!$A:$A,"1_Operational"),"",INDEX(Operational_RawData!E:E,MATCH("1_Operational",Operational_RawData!$A:$A,0)+ROWS($2:3)-1)) -> 3.51 | F3: =IF(ROWS($2:3)>COUNTIF(Operational_RawData!$A:$A,"1_Operational"),"",INDEX(Operational_RawData!F:F,MATCH("1_Operational",Operational_RawData!$A:$A,0)+ROWS($2:3)-1)) -> 269.6 | G3: =IF(ROWS($2:3)>COUNTIF(Operational_RawData!$A:$A,"1_Operational"),"",INDEX(Operational_RawData!G:G,MATCH("1_Operational",Operational_RawData!$A:$A,0)+ROWS($2:3)-1)) -> 269.6 | H3: =IF(ROWS($2:3)>COUNTIF(Operational_RawData!$A:$A,"1_Operational"),"",INDEX(Operational_RawData!H:H,MATCH("1_Operational",Operational_RawData!$A:$A,0)+ROWS($2:3)-1)) -> 269.6 | I3: =IF(ROWS($2:3)>COUNTIF(Operational_RawData!$A:$A,"1_Operational"),"",INDEX(Operational_RawData!I:I,MATCH("1_Operational",Operational_RawData!$A:$A,0)+ROWS($2:3)-1)) -> 269.6 | J3: =IF(ROWS($2:3)>COUNTIF(Operational_RawData!$A:$A,"1_Operational"),"",INDEX(Operational_RawData!J:J,MATCH("1_Operational",Operational_RawData!$A:$A,0)+ROWS($2:3)-1)) -> 351.84 | K3: =IF(ROWS($2:3)>COUNTIF(Operational_RawData!$A:$A,"1_Operational"),"",INDEX(Operational_RawData!K:K,MATCH("1_Operational",Operational_RawData!$A:$A,0)+ROWS($2:3)-1)) -> 351.84 | L3: =IF(ROWS($2:3)>COUNTIF(Operational_RawData!$A:$A,"1_Operational"),"",INDEX(Operational_RawData!L:L,MATCH("1_Operational",Operational_RawData!$A:$A,0)+ROWS($2:3)-1)) -> 351.84 | M3: =IF(ROWS($2:3)>COUNTIF(Operational_RawData!$A:$A,"1_Operational"),"",INDEX(Operational_RawData!M:M,MATCH("1_Operational",Operational_RawData!$A:$A,0)+ROWS($2:3)-1)) -> 351.84 | N3: =IF(ROWS($2:3)>COUNTIF(Operational_RawData!$A:$A,"1_Operational"),"",INDEX(Operational_RawData!N:N,MATCH("1_Operational",Operational_RawData!$A:$A,0)+ROWS($2:3)-1)) -> 0.06 | O3: =IF(ROWS($2:3)>COUNTIF(Operational_RawData!$A:$A,"1_Operational"),"",INDEX(Operational_RawData!O:O,MATCH("1_Operational",Operational_RawData!$A:$A,0)+ROWS($2:3)-1)) -> 0.19 | P3: =IF(ROWS($2:3)>COUNTIF(Operational_RawData!$A:$A,"1_Operational"),"",INDEX(Operational_RawData!P:P,MATCH("1_Operational",Operational_RawData!$A:$A,0)+ROWS($2:3)-1)) -> 0.06 | Q3: =IF(ROWS($2:3)>COUNTIF(Operational_RawData!$A:$A,"1_Operational"),"",INDEX(Operational_RawData!Q:Q,MATCH("1_Operational",Operational_RawData!$A:$A,0)+ROWS($2:3)-1)) -> 0.1 | R3: =IF(ROWS($2:3)>COUNTIF(Operational_RawData!$A:$A,"1_Operational"),"",INDEX(Operational_RawData!R:R,MATCH("1_Operational",Operational_RawData!$A:$A,0)+ROWS($2:3)-1)) -> Pass | S3: =IF(ROWS($2:3)>COUNTIF(Operational_RawData!$A:$A,"1_Operational"),"",INDEX(Operational_RawData!S:S,MATCH("1_Operational",Operational_RawData!$A:$A,0)+ROWS($2:3)-1)) -> 0 | T3: =IF(ROWS($2:3)>COUNTIF(Operational_RawData!$A:$A,"1_Operational"),"",INDEX(Operational_RawData!T:T,MATCH("1_Operational",Operational_RawData!$A:$A,0)+ROWS($2:3)-1)) -> 0
A4: =IF(ROWS($2:4)>COUNTIF(Operational_RawData!$A:$A,"1_Operational"),"",INDEX(Operational_RawData!A:A,MATCH("1_Operational",Operational_RawData!$A:$A,0)+ROWS($2:4)-1)) -> 1_Operational | B4: =IF(ROWS($2:4)>COUNTIF(Operational_RawData!$A:$A,"1_Operational"),"",INDEX(Operational_RawData!B:B,MATCH("1_Operational",Operational_RawData!$A:$A,0)+ROWS($2:4)-1)) -> 144416.82 | C4: =IF(ROWS($2:4)>COUNTIF(Operational_RawData!$A:$A,"1_Operational"),"",INDEX(Operational_RawData!C:C,MATCH("1_Operational",Operational_RawData!$A:$A,0)+ROWS($2:4)-1)) -> 1.7 | D4: =IF(ROWS($2:4)>COUNTIF(Operational_RawData!$A:$A,"1_Operational"),"",INDEX(Operational_RawData!D:D,MATCH("1_Operational",Operational_RawData!$A:$A,0)+ROWS($2:4)-1)) -> 1307.402 | E4: =IF(ROWS($2:4)>COUNTIF(Operational_RawData!$A:$A,"1_Operational"),"",INDEX(Operational_RawData!E:E,MATCH("1_Operational",Operational_RawData!$A:$A,0)+ROWS($2:4)-1)) -> 3.55 | F4: =IF(ROWS($2:4)>COUNTIF(Operational_RawData!$A:$A,"1_Operational"),"",INDEX(Operational_RawData!F:F,MATCH("1_Operational",Operational_RawData!$A:$A,0)+ROWS($2:4)-1)) -> 267.84 | G4: =IF(ROWS($2:4)>COUNTIF(Operational_RawData!$A:$A,"1_Operational"),"",INDEX(Operational_RawData!G:G,MATCH("1_Operational",Operational_RawData!$A:$A,0)+ROWS($2:4)-1)) -> 267.84 | H4: =IF(ROWS($2:4)>COUNTIF(Operational_RawData!$A:$A,"1_Operational"),"",INDEX(Operational_RawData!H:H,MATCH("1_Operational",Operational_RawData!$A:$A,0)+ROWS($2:4)-1)) -> 267.84 | I4: =IF(ROWS($2:4)>COUNTIF(Operational_RawData!$A:$A,"1_Operational"),"",INDEX(Operational_RawData!I:I,MATCH("1_Operational",Operational_RawData!$A:$A,0)+ROWS($2:4)-1)) -> 267.84 | J4: =IF(ROWS($2:4)>COUNTIF(Operational_RawData!$A:$A,"1_Operational"),"",INDEX(Operational_RawData!J:J,MATCH("1_Operational",Operational_RawData!$A:$A,0)+ROWS($2:4)-1)) -> 351.28 | K4: =IF(ROWS($2:4)>COUNTIF(Operational_RawData!$A:$A,"1_Operational"),"",INDEX(Operational_RawData!K:K,MATCH("1_Operational",Operational_RawData!$A:$A,0)+ROWS($2:4)-1)) -> 351.28 | L4: =IF(ROWS($2:4)>COUNTIF(Operational_RawData!$A:$A,"1_Operational"),"",INDEX(Operational_RawData!L:L,MATCH("1_Operational",Operational_RawData!$A:$A,0)+ROWS($2:4)-1)) -> 351.28 | M4: =IF(ROWS($2:4)>COUNTIF(Operational_RawData!$A:$A,"1_Operational"),"",INDEX(Operational_RawData!M:M,MATCH("1_Operational",Operational_RawData!$A:$A,0)+ROWS($2:4)-1)) -> 351.28 | N4: =IF(ROWS($2:4)>COUNTIF(Operational_RawData!$A:$A,"1_Operational"),"",INDEX(Operational_RawData!N:N,MATCH("1_Operational",Operational_RawData!$A:$A,0)+ROWS($2:4)-1)) -> 0.07 | O4: =IF(ROWS($2:4)>COUNTIF(Operational_RawData!$A:$A,"1_Operational"),"",INDEX(Operational_RawData!O:O,MATCH("1_Operational",Operational_RawData!$A:$A,0)+ROWS($2:4)-1)) -> 0.19 | P4: =IF(ROWS($2:4)>COUNTIF(Operational_RawData!$A:$A,"1_Operational"),"",INDEX(Operational_RawData!P:P,MATCH("1_Operational",Operational_RawData!$A:$A,0)+ROWS($2:4)-1)) -> 0.06 | Q4: =IF(ROWS($2:4)>COUNTIF(Operational_RawData!$A:$A,"1_Operational"),"",INDEX(Operational_RawData!Q:Q,MATCH("1_Operational",Operational_RawData!$A:$A,0)+ROWS($2:4)-1)) -> 0.1 | R4: =IF(ROWS($2:4)>COUNTIF(Operational_RawData!$A:$A,"1_Operational"),"",INDEX(Operational_RawData!R:R,MATCH("1_Operational",Operational_RawData!$A:$A,0)+ROWS($2:4)-1)) -> Pass | S4: =IF(ROWS($2:4)>COUNTIF(Operational_RawData!$A:$A,"1_Operational"),"",INDEX(Operational_RawData!S:S,MATCH("1_Operational",Operational_RawData!$A:$A,0)+ROWS($2:4)-1)) -> 0 | T4: =IF(ROWS($2:4)>COUNTIF(Operational_RawData!$A:$A,"1_Operational"),"",INDEX(Operational_RawData!T:T,MATCH("1_Operational",Operational_RawData!$A:$A,0)+ROWS($2:4)-1)) -> 0
A5: =IF(ROWS($2:5)>COUNTIF(Operational_RawData!$A:$A,"1_Operational"),"",INDEX(Operational_RawData!A:A,MATCH("1_Operational",Operational_RawData!$A:$A,0)+ROWS($2:5)-1)) -> 1_Operational | B5: =IF(ROWS($2:5)>COUNTIF(Operational_RawData!$A:$A,"1_Operational"),"",INDEX(Operational_RawData!B:B,MATCH("1_Operational",Operational_RawData!$A:$A,0)+ROWS($2:5)-1)) -> 144421.83 | C5: =IF(ROWS($2:5)>COUNTIF(Operational_RawData!$A:$A,"1_Operational"),"",INDEX(Operational_RawData!C:C,MATCH("1_Operational",Operational_RawData!$A:$A,0)+ROWS($2:5)-1)) -> 2.43 | D5: =IF(ROWS($2:5)>COUNTIF(Operational_RawData!$A:$A,"1_Operational"),"",INDEX(Operational_RawData!D:D,MATCH("1_Operational",Operational_RawData!$A:$A,0)+ROWS($2:5)-1)) -> 1307.446 | E5: =IF(ROWS($2:5)>COUNTIF(Operational_RawData!$A:$A,"1_Operational"),"",INDEX(Operational_RawData!E:E,MATCH("1_Operational",Operational_RawData!$A:$A,0)+ROWS($2:5)-1)) -> 3.52 | F5: =IF(ROWS($2:5)>COUNTIF(Operational_RawData!$A:$A,"1_Operational"),"",INDEX(Operational_RawData!F:F,MATCH("1_Operational",Operational_RawData!$A:$A,0)+ROWS($2:5)-1)) -> 265.8 | G5: =IF(ROWS($2:5)>COUNTIF(Operational_RawData!$A:$A,"1_Operational"),"",INDEX(Operational_RawData!G:G,MATCH("1_Operational",Operational_RawData!$A:$A,0)+ROWS($2:5)-1)) -> 265.8 | H5: =IF(ROWS($2:5)>COUNTIF(Operational_RawData!$A:$A,"1_Operational"),"",INDEX(Operational_RawData!H:H,MATCH("1_Operational",Operational_RawData!$A:$A,0)+ROWS($2:5)-1)) -> 265.8 | I5: =IF(ROWS($2:5)>COUNTIF(Operational_RawData!$A:$A,"1_Operational"),"",INDEX(Operational_RawData!I:I,MATCH("1_Operational",Operational_RawData!$A:$A,0)+ROWS($2:5)-1)) -> 265.8 | J5: =IF(ROWS($2:5)>COUNTIF(Operational_RawData!$A:$A,"1_Operational"),"",INDEX(Operational_RawData!J:J,MATCH("1_Operational",Operational_RawData!$A:$A,0)+ROWS($2:5)-1)) -> 350.48 | K5: =IF(ROWS($2:5)>COUNTIF(Operational_RawData!$A:$A,"1_Operational"),"",INDEX(Operational_RawData!K:K,MATCH("1_Operational",Operational_RawData!$A:$A,0)+ROWS($2:5)-1)) -> 350.48 | L5: =IF(ROWS($2:5)>COUNTIF(Operational_RawData!$A:$A,"1_Operational"),"",INDEX(Operational_RawData!L:L,MATCH("1_Operational",Operational_RawData!$A:$A,0)+ROWS($2:5)-1)) -> 350.48 | M5: =IF(ROWS($2:5)>COUNTIF(Operational_RawData!$A:$A,"1_Operational"),"",INDEX(Operational_RawData!M:M,MATCH("1_Operational",Operational_RawData!$A:$A,0)+ROWS($2:5)-1)) -> 350.48 | N5: =IF(ROWS($2:5)>COUNTIF(Operational_RawData!$A:$A,"1_Operational"),"",INDEX(Operational_RawData!N:N,MATCH("1_Operational",Operational_RawData!$A:$A,0)+ROWS($2:5)-1)) -> 0.06 | O5: =IF(ROWS($2:5)>COUNTIF(Operational_RawData!$A:$A,"1_Operational"),"",INDEX(Operational_RawData!O:O,MATCH("1_Operational",Operational_RawData!$A:$A,0)+ROWS($2:5)-1)) -> 0.19 | P5: =IF(ROWS($2:5)>COUNTIF(Operational_RawData!$A:$A,"1_Operational"),"",INDEX(Operational_RawData!P:P,MATCH("1_Operational",Operational_RawData!$A:$A,0)+ROWS($2:5)-1)) -> 0.06 | Q5: =IF(ROWS($2:5)>COUNTIF(Operational_RawData!$A:$A,"1_Operational"),"",INDEX(Operational_RawData!Q:Q,MATCH("1_Operational",Operational_RawData!$A:$A,0)+ROWS($2:5)-1)) -> 0.1 | R5: =IF(ROWS($2:5)>COUNTIF(Operational_RawData!$A:$A,"1_Operational"),"",INDEX(Operational_RawData!R:R,MATCH("1_Operational",Operational_RawData!$A:$A,0)+ROWS($2:5)-1)) -> Pass | S5: =IF(ROWS($2:5)>COUNTIF(Operational_RawData!$A:$A,"1_Operational"),"",INDEX(Operational_RawData!S:S,MATCH("1_Operational",Operational_RawData!$A:$A,0)+ROWS($2:5)-1)) -> 0 | T5: =IF(ROWS($2:5)>COUNTIF(Operational_RawData!$A:$A,"1_Operational"),"",INDEX(Operational_RawData!T:T,MATCH("1_Operational",Operational_RawData!$A:$A,0)+ROWS($2:5)-1)) -> 0
A6: =IF(ROWS($2:6)>COUNTIF(Operational_RawData!$A:$A,"1_Operational"),"",INDEX(Operational_RawData!A:A,MATCH("1_Operational",Operational_RawData!$A:$A,0)+ROWS($2:6)-1)) -> 1_Operational | B6: =IF(ROWS($2:6)>COUNTIF(Operational_RawData!$A:$A,"1_Operational"),"",INDEX(Operational_RawData!B:B,MATCH("1_Operational",Operational_RawData!$A:$A,0)+ROWS($2:6)-1)) -> 144426.83 | C6: =IF(ROWS($2:6)>COUNTIF(Operational_RawData!$A:$A,"1_Operational"),"",INDEX(Operational_RawData!C:C,MATCH("1_Operational",Operational_RawData!$A:$A,0)+ROWS($2:6)-1)) -> 3.16 | D6: =IF(ROWS($2:6)>COUNTIF(Operational_RawData!$A:$A,"1_Operational"),"",INDEX(Operational_RawData!D:D,MATCH("1_Operational",Operational_RawData!$A:$A,0)+ROWS($2:6)-1)) -> 1307.502 | E6: =IF(ROWS($2:6)>COUNTIF(Operational_RawData!$A:$A,"1_Operational"),"",INDEX(Operational_RawData!E:E,MATCH("1_Operational",Operational_RawData!$A:$A,0)+ROWS($2:6)-1)) -> 3.51 | F6: =IF(ROWS($2:6)>COUNTIF(Operational_RawData!$A:$A,"1_Operational"),"",INDEX(Operational_RawData!F:F,MATCH("1_Operational",Operational_RawData!$A:$A,0)+ROWS($2:6)-1)) -> 264 | G6: =IF(ROWS($2:6)>COUNTIF(Operational_RawData!$A:$A,"1_Operational"),"",INDEX(Operational_RawData!G:G,MATCH("1_Operational",Operational_RawData!$A:$A,0)+ROWS($2:6)-1)) -> 264 | H6: =IF(ROWS($2:6)>COUNTIF(Operational_RawData!$A:$A,"1_Operational"),"",INDEX(Operational_RawData!H:H,MATCH("1_Operational",Operational_RawData!$A:$A,0)+ROWS($2:6)-1)) -> 264 | I6: =IF(ROWS($2:6)>COUNTIF(Operational_RawData!$A:$A,"1_Operational"),"",INDEX(Operational_RawData!I:I,MATCH("1_Operational",Operational_RawData!$A:$A,0)+ROWS($2:6)-1)) -> 264 | J6: =IF(ROWS($2:6)>COUNTIF(Operational_RawData!$A:$A,"1_Operational"),"",INDEX(Operational_RawData!J:J,MATCH("1_Operational",Operational_RawData!$A:$A,0)+ROWS($2:6)-1)) -> 349.64 | K6: =IF(ROWS($2:6)>COUNTIF(Operational_RawData!$A:$A,"1_Operational"),"",INDEX(Operational_RawData!K:K,MATCH("1_Operational",Operational_RawData!$A:$A,0)+ROWS($2:6)-1)) -> 349.64 | L6: =IF(ROWS($2:6)>COUNTIF(Operational_RawData!$A:$A,"1_Operational"),"",INDEX(Operational_RawData!L:L,MATCH("1_Operational",Operational_RawData!$A:$A,0)+ROWS($2:6)-1)) -> 349.64 | M6: =IF(ROWS($2:6)>COUNTIF(Operational_RawData!$A:$A,"1_Operational"),"",INDEX(Operational_RawData!M:M,MATCH("1_Operational",Operational_RawData!$A:$A,0)+ROWS($2:6)-1)) -> 349.64 | N6: =IF(ROWS($2:6)>COUNTIF(Operational_RawData!$A:$A,"1_Operational"),"",INDEX(Operational_RawData!N:N,MATCH("1_Operational",Operational_RawData!$A:$A,0)+ROWS($2:6)-1)) -> 0.08 | O6: =IF(ROWS($2:6)>COUNTIF(Operational_RawData!$A:$A,"1_Operational"),"",INDEX(Operational_RawData!O:O,MATCH("1_Operational",Operational_RawData!$A:$A,0)+ROWS($2:6)-1)) -> 0.19 | P6: =IF(ROWS($2:6)>COUNTIF(Operational_RawData!$A:$A,"1_Operational"),"",INDEX(Operational_RawData!P:P,MATCH("1_Operational",Operational_RawData!$A:$A,0)+ROWS($2:6)-1)) -> 0.06 | Q6: =IF(ROWS($2:6)>COUNTIF(Operational_RawData!$A:$A,"1_Operational"),"",INDEX(Operational_RawData!Q:Q,MATCH("1_Operational",Operational_RawData!$A:$A,0)+ROWS($2:6)-1)) -> 0.1 | R6: =IF(ROWS($2:6)>COUNTIF(Operational_RawData!$A:$A,"1_Operational"),"",INDEX(Operational_RawData!R:R,MATCH("1_Operational",Operational_RawData!$A:$A,0)+ROWS($2:6)-1)) -> Pass | S6: =IF(ROWS($2:6)>COUNTIF(Operational_RawData!$A:$A,"1_Operational"),"",INDEX(Operational_RawData!S:S,MATCH("1_Operational",Operational_RawData!$A:$A,0)+ROWS($2:6)-1)) -> 0 | T6: =IF(ROWS($2:6)>COUNTIF(Operational_RawData!$A:$A,"1_Operational"),"",INDEX(Operational_RawData!T:T,MATCH("1_Operational",Operational_RawData!$A:$A,0)+ROWS($2:6)-1)) -> 0
A7: =IF(ROWS($2:7)>COUNTIF(Operational_RawData!$A:$A,"1_Operational"),"",INDEX(Operational_RawData!A:A,MATCH("1_Operational",Operational_RawData!$A:$A,0)+ROWS($2:7)-1)) -> 1_Operational | B7: =IF(ROWS($2:7)>COUNTIF(Operational_RawData!$A:$A,"1_Operational"),"",INDEX(Operational_RawData!B:B,MATCH("1_Operational",Operational_RawData!$A:$A,0)+ROWS($2:7)-1)) -> 144431.83 | C7: =IF(ROWS($2:7)>COUNTIF(Operational_RawData!$A:$A,"1_Operational"),"",INDEX(Operational_RawData!C:C,MATCH("1_Operational",Operational_RawData!$A:$A,0)+ROWS($2:7)-1)) -> 3.91 | D7: =IF(ROWS($2:7)>COUNTIF(Operational_RawData!$A:$A,"1_Operational"),"",INDEX(Operational_RawData!D:D,MATCH("1_Operational",Operational_RawData!$A:$A,0)+ROWS($2:7)-1)) -> 1307.554 | E7: =IF(ROWS($2:7)>COUNTIF(Operational_RawData!$A:$A,"1_Operational"),"",INDEX(Operational_RawData!E:E,MATCH("1_Operational",Operational_RawData!$A:$A,0)+ROWS($2:7)-1)) -> 3.56 | F7: =IF(ROWS($2:7)>COUNTIF(Operational_RawData!$A:$A,"1_Operational"),"",INDEX(Operational_RawData!F:F,MATCH("1_Operational",Operational_RawData!$A:$A,0)+ROWS($2:7)-1)) -> 261.8 | G7: =IF(ROWS($2:7)>COUNTIF(Operational_RawData!$A:$A,"1_Operational"),"",INDEX(Operational_RawData!G:G,MATCH("1_Operational",Operational_RawData!$A:$A,0)+ROWS($2:7)-1)) -> 261.8 | H7: =IF(ROWS($2:7)>COUNTIF(Operational_RawData!$A:$A,"1_Operational"),"",INDEX(Operational_RawData!H:H,MATCH("1_Operational",Operational_RawData!$A:$A,0)+ROWS($2:7)-1)) -> 261.8 | I7: =IF(ROWS($2:7)>COUNTIF(Operational_RawData!$A:$A,"1_Operational"),"",INDEX(Operational_RawData!I:I,MATCH("1_Operational",Operational_RawData!$A:$A,0)+ROWS($2:7)-1)) -> 261.8 | J7: =IF(ROWS($2:7)>COUNTIF(Operational_RawData!$A:$A,"1_Operational"),"",INDEX(Operational_RawData!J:J,MATCH("1_Operational",Operational_RawData!$A:$A,0)+ROWS($2:7)-1)) -> 348.64 | K7: =IF(ROWS($2:7)>COUNTIF(Operational_RawData!$A:$A,"1_Operational"),"",INDEX(Operational_RawData!K:K,MATCH("1_Operational",Operational_RawData!$A:$A,0)+ROWS($2:7)-1)) -> 348.64 | L7: =IF(ROWS($2:7)>COUNTIF(Operational_RawData!$A:$A,"1_Operational"),"",INDEX(Operational_RawData!L:L,MATCH("1_Operational",Operational_RawData!$A:$A,0)+ROWS($2:7)-1)) -> 348.64 | M7: =IF(ROWS($2:7)>COUNTIF(Operational_RawData!$A:$A,"1_Operational"),"",INDEX(Operational_RawData!M:M,MATCH("1_Operational",Operational_RawData!$A:$A,0)+ROWS($2:7)-1)) -> 348.64 | N7: =IF(ROWS($2:7)>COUNTIF(Operational_RawData!$A:$A,"1_Operational"),"",INDEX(Operational_RawData!N:N,MATCH("1_Operational",Operational_RawData!$A:$A,0)+ROWS($2:7)-1)) -> 0.07 | O7: =IF(ROWS($2:7)>COUNTIF(Operational_RawData!$A:$A,"1_Operational"),"",INDEX(Operational_RawData!O:O,MATCH("1_Operational",Operational_RawData!$A:$A,0)+ROWS($2:7)-1)) -> 0.19 | P7: =IF(ROWS($2:7)>COUNTIF(Operational_RawData!$A:$A,"1_Operational"),"",INDEX(Operational_RawData!P:P,MATCH("1_Operational",Operational_RawData!$A:$A,0)+ROWS($2:7)-1)) -> 0.06 | Q7: =IF(ROWS($2:7)>COUNTIF(Operational_RawData!$A:$A,"1_Operational"),"",INDEX(Operational_RawData!Q:Q,MATCH("1_Operational",Operational_RawData!$A:$A,0)+ROWS($2:7)-1)) -> 0.1 | R7: =IF(ROWS($2:7)>COUNTIF(Operational_RawData!$A:$A,"1_Operational"),"",INDEX(Operational_RawData!R:R,MATCH("1_Operational",Operational_RawData!$A:$A,0)+ROWS($2:7)-1)) -> Pass | S7: =IF(ROWS($2:7)>COUNTIF(Operational_RawData!$A:$A,"1_Operational"),"",INDEX(Operational_RawData!S:S,MATCH("1_Operational",Operational_RawData!$A:$A,0)+ROWS($2:7)-1)) -> 0 | T7: =IF(ROWS($2:7)>COUNTIF(Operational_RawData!$A:$A,"1_Operational"),"",INDEX(Operational_RawData!T:T,MATCH("1_Operational",Operational_RawData!$A:$A,0)+ROWS($2:7)-1)) -> 0
A8: =IF(ROWS($2:8)>COUNTIF(Operational_RawData!$A:$A,"1_Operational"),"",INDEX(Operational_RawData!A:A,MATCH("1_Operational",Operational_RawData!$A:$A,0)+ROWS($2:8)-1)) -> 1_Operational | B8: =IF(ROWS($2:8)>COUNTIF(Operational_RawData!$A:$A,"1_Operational"),"",INDEX(Operational_RawData!B:B,MATCH("1_Operational",Operational_RawData!$A:$A,0)+ROWS($2:8)-1)) -> 144436.84 | C8: =IF(ROWS($2:8)>COUNTIF(Operational_RawData!$A:$A,"1_Operational"),"",INDEX(Operational_RawData!C:C,MATCH("1_Operational",Operational_RawData!$A:$A,0)+ROWS($2:8)-1)) -> 4.64 | D8: =IF(ROWS($2:8)>COUNTIF(Operational_RawData!$A:$A,"1_Operational"),"",INDEX(Operational_RawData!D:D,MATCH("1_Operational",Operational_RawData!$A:$A,0)+ROWS($2:8)-1)) -> 1307.607 | E8: =IF(ROWS($2:8)>COUNTIF(Operational_RawData!$A:$A,"1_Operational"),"",INDEX(Operational_RawData!E:E,MATCH("1_Operational",Operational_RawData!$A:$A,0)+ROWS($2:8)-1)) -> 3.57 | F8: =IF(ROWS($2:8)>COUNTIF(Operational_RawData!$A:$A,"1_Operational"),"",INDEX(Operational_RawData!F:F,MATCH("1_Operational",Operational_RawData!$A:$A,0)+ROWS($2:8)-1)) -> 259.72 | G8: =IF(ROWS($2:8)>COUNTIF(Operational_RawData!$A:$A,"1_Operational"),"",INDEX(Operational_RawData!G:G,MATCH("1_Operational",Operational_RawData!$A:$A,0)+ROWS($2:8)-1)) -> 259.72 | H8: =IF(ROWS($2:8)>COUNTIF(Operational_RawData!$A:$A,"1_Operational"),"",INDEX(Operational_RawData!H:H,MATCH("1_Operational",Operational_RawData!$A:$A,0)+ROWS($2:8)-1)) -> 259.72 | I8: =IF(ROWS($2:8)>COUNTIF(Operational_RawData!$A:$A,"1_Operational"),"",INDEX(Operational_RawData!I:I,MATCH("1_Operational",Operational_RawData!$A:$A,0)+ROWS($2:8)-1)) -> 259.72 | J8: =IF(ROWS($2:8)>COUNTIF(Operational_RawData!$A:$A,"1_Operational"),"",INDEX(Operational_RawData!J:J,MATCH("1_Operational",Operational_RawData!$A:$A,0)+ROWS($2:8)-1)) -> 347.64 | K8: =IF(ROWS($2:8)>COUNTIF(Operational_RawData!$A:$A,"1_Operational"),"",INDEX(Operational_RawData!K:K,MATCH("1_Operational",Operational_RawData!$A:$A,0)+ROWS($2:8)-1)) -> 347.64 | L8: =IF(ROWS($2:8)>COUNTIF(Operational_RawData!$A:$A,"1_Operational"),"",INDEX(Operational_RawData!L:L,MATCH("1_Operational",Operational_RawData!$A:$A,0)+ROWS($2:8)-1)) -> 347.64 | M8: =IF(ROWS($2:8)>COUNTIF(Operational_RawData!$A:$A,"1_Operational"),"",INDEX(Operational_RawData!M:M,MATCH("1_Operational",Operational_RawData!$A:$A,0)+ROWS($2:8)-1)) -> 347.64 | N8: =IF(ROWS($2:8)>COUNTIF(Operational_RawData!$A:$A,"1_Operational"),"",INDEX(Operational_RawData!N:N,MATCH("1_Operational",Operational_RawData!$A:$A,0)+ROWS($2:8)-1)) -> 0.07 | O8: =IF(ROWS($2:8)>COUNTIF(Operational_RawData!$A:$A,"1_Operational"),"",INDEX(Operational_RawData!O:O,MATCH("1_Operational",Operational_RawData!$A:$A,0)+ROWS($2:8)-1)) -> 0.19 | P8: =IF(ROWS($2:8)>COUNTIF(Operational_RawData!$A:$A,"1_Operational"),"",INDEX(Operational_RawData!P:P,MATCH("1_Operational",Operational_RawData!$A:$A,0)+ROWS($2:8)-1)) -> 0.06 | Q8: =IF(ROWS($2:8)>COUNTIF(Operational_RawData!$A:$A,"1_Operational"),"",INDEX(Operational_RawData!Q:Q,MATCH("1_Operational",Operational_RawData!$A:$A,0)+ROWS($2:8)-1)) -> 0.1 | R8: =IF(ROWS($2:8)>COUNTIF(Operational_RawData!$A:$A,"1_Operational"),"",INDEX(Operational_RawData!R:R,MATCH("1_Operational",Operational_RawData!$A:$A,0)+ROWS($2:8)-1)) -> Pass | S8: =IF(ROWS($2:8)>COUNTIF(Operational_RawData!$A:$A,"1_Operational"),"",INDEX(Operational_RawData!S:S,MATCH("1_Operational",Operational_RawData!$A:$A,0)+ROWS($2:8)-1)) -> 0 | T8: =IF(ROWS($2:8)>COUNTIF(Operational_RawData!$A:$A,"1_Operational"),"",INDEX(Operational_RawData!T:T,MATCH("1_Operational",Operational_RawData!$A:$A,0)+ROWS($2:8)-1)) -> 0
A9: =IF(ROWS($2:9)>COUNTIF(Operational_RawData!$A:$A,"1_Operational"),"",INDEX(Operational_RawData!A:A,MATCH("1_Operational",Operational_RawData!$A:$A,0)+ROWS($2:9)-1)) -> 1_Operational | B9: =IF(ROWS($2:9)>COUNTIF(Operational_RawData!$A:$A,"1_Operational"),"",INDEX(Operational_RawData!B:B,MATCH("1_Operational",Operational_RawData!$A:$A,0)+ROWS($2:9)-1)) -> 144441.83 | C9: =IF(ROWS($2:9)>COUNTIF(Operational_RawData!$A:$A,"1_Operational"),"",INDEX(Operational_RawData!C:C,MATCH("1_Operational",Operational_RawData!$A:$A,0)+ROWS($2:9)-1)) -> 5.39 | D9: =IF(ROWS($2:9)>COUNTIF(Operational_RawData!$A:$A,"1_Operational"),"",INDEX(Operational_RawData!D:D,MATCH("1_Operational",Operational_RawData!$A:$A,0)+ROWS($2:9)-1)) -> 1307.66 | E9: =IF(ROWS($2:9)>COUNTIF(Operational_RawData!$A:$A,"1_Operational"),"",INDEX(Operational_RawData!E:E,MATCH("1_Operational",Operational_RawData!$A:$A,0)+ROWS($2:9)-1)) -> 3.57 | F9: =IF(ROWS($2:9)>COUNTIF(Operational_RawData!$A:$A,"1_Operational"),"",INDEX(Operational_RawData!F:F,MATCH("1_Operational",Operational_RawData!$A:$A,0)+ROWS($2:9)-1)) -> 257.64 | G9: =IF(ROWS($2:9)>COUNTIF(Operational_RawData!$A:$A,"1_Operational"),"",INDEX(Operational_RawData!G:G,MATCH("1_Operational",Operational_RawData!$A:$A,0)+ROWS($2:9)-1)) -> 257.64 | H9: =IF(ROWS($2:9)>COUNTIF(Operational_RawData!$A:$A,"1_Operational"),"",INDEX(Operational_RawData!H:H,MATCH("1_Operational",Operational_RawData!$A:$A,0)+ROWS($2:9)-1)) -> 257.64 | I9: =IF(ROWS($2:9)>COUNTIF(Operational_RawData!$A:$A,"1_Operational"),"",INDEX(Operational_RawData!I:I,MATCH("1_Operational",Operational_RawData!$A:$A,0)+ROWS($2:9)-1)) -> 257.64 | J9: =IF(ROWS($2:9)>COUNTIF(Operational_RawData!$A:$A,"1_Operational"),"",INDEX(Operational_RawData!J:J,MATCH("1_Operational",Operational_RawData!$A:$A,0)+ROWS($2:9)-1)) -> 346.6 | K9: =IF(ROWS($2:9)>COUNTIF(Operational_RawData!$A:$A,"1_Operational"),"",INDEX(Operational_RawData!K:K,MATCH("1_Operational",Operational_RawData!$A:$A,0)+ROWS($2:9)-1)) -> 346.6 | L9: =IF(ROWS($2:9)>COUNTIF(Operational_RawData!$A:$A,"1_Operational"),"",INDEX(Operational_RawData!L:L,MATCH("1_Operational",Operational_RawData!$A:$A,0)+ROWS($2:9)-1)) -> 346.6 | M9: =IF(ROWS($2:9)>COUNTIF(Operational_RawData!$A:$A,"1_Operational"),"",INDEX(Operational_RawData!M:M,MATCH("1_Operational",Operational_RawData!$A:$A,0)+ROWS($2:9)-1)) -> 346.6 | N9: =IF(ROWS($2:9)>COUNTIF(Operational_RawData!$A:$A,"1_Operational"),"",INDEX(Operational_RawData!N:N,MATCH("1_Operational",Operational_RawData!$A:$A,0)+ROWS($2:9)-1)) -> 0.07 | O9: =IF(ROWS($2:9)>COUNTIF(Operational_RawData!$A:$A,"1_Operational"),"",INDEX(Operational_RawData!O:O,MATCH("1_Operational",Operational_RawData!$A:$A,0)+ROWS($2:9)-1)) -> 0.19 | P9: =IF(ROWS($2:9)>COUNTIF(Operational_RawData!$A:$A,"1_Operational"),"",INDEX(Operational_RawData!P:P,MATCH("1_Operational",Operational_RawData!$A:$A,0)+ROWS($2:9)-1)) -> 0.06 | Q9: =IF(ROWS($2:9)>COUNTIF(Operational_RawData!$A:$A,"1_Operational"),"",INDEX(Operational_RawData!Q:Q,MATCH("1_Operational",Operational_RawData!$A:$A,0)+ROWS($2:9)-1)) -> 0.1 | R9: =IF(ROWS($2:9)>COUNTIF(Operational_RawData!$A:$A,"1_Operational"),"",INDEX(Operational_RawData!R:R,MATCH("1_Operational",Operational_RawData!$A:$A,0)+ROWS($2:9)-1)) -> Pass | S9: =IF(ROWS($2:9)>COUNTIF(Operational_RawData!$A:$A,"1_Operational"),"",INDEX(Operational_RawData!S:S,MATCH("1_Operational",Operational_RawData!$A:$A,0)+ROWS($2:9)-1)) -> 0 | T9: =IF(ROWS($2:9)>COUNTIF(Operational_RawData!$A:$A,"1_Operational"),"",INDEX(Operational_RawData!T:T,MATCH("1_Operational",Operational_RawData!$A:$A,0)+ROWS($2:9)-1)) -> 0
A10: =IF(ROWS($2:10)>COUNTIF(Operational_RawData!$A:$A,"1_Operational"),"",INDEX(Operational_RawData!A:A,MATCH("1_Operational",Operational_RawData!$A:$A,0)+ROWS($2:10)-1)) -> 1_Operational | B10: =IF(ROWS($2:10)>COUNTIF(Operational_RawData!$A:$A,"1_Operational"),"",INDEX(Operational_RawData!B:B,MATCH("1_Operational",Operational_RawData!$A:$A,0)+ROWS($2:10)-1)) -> 144446.83 | C10: =IF(ROWS($2:10)>COUNTIF(Operational_RawData!$A:$A,"1_Operational"),"",INDEX(Operational_RawData!C:C,MATCH("1_Operational",Operational_RawData!$A:$A,0)+ROWS($2:10)-1)) -> 6.13 | D10: =IF(ROWS($2:10)>COUNTIF(Operational_RawData!$A:$A,"1_Operational"),"",INDEX(Operational_RawData!D:D,MATCH("1_Operational",Operational_RawData!$A:$A,0)+ROWS($2:10)-1)) -> 1307.713 | E10: =IF(ROWS($2:10)>COUNTIF(Operational_RawData!$A:$A,"1_Operational"),"",INDEX(Operational_RawData!E:E,MATCH("1_Operational",Operational_RawData!$A:$A,0)+ROWS($2:10)-1)) -> 3.58 | F10: =IF(ROWS($2:10)>COUNTIF(Operational_RawData!$A:$A,"1_Operational"),"",INDEX(Operational_RawData!F:F,MATCH("1_Operational",Operational_RawData!$A:$A,0)+ROWS($2:10)-1)) -> 255.4 | G10: =IF(ROWS($2:10)>COUNTIF(Operational_RawData!$A:$A,"1_Operational"),"",INDEX(Operational_RawData!G:G,MATCH("1_Operational",Operational_RawData!$A:$A,0)+ROWS($2:10)-1)) -> 255.4 | H10: =IF(ROWS($2:10)>COUNTIF(Operational_RawData!$A:$A,"1_Operational"),"",INDEX(Operational_RawData!H:H,MATCH("1_Operational",Operational_RawData!$A:$A,0)+ROWS($2:10)-1)) -> 255.4 | I10: =IF(ROWS($2:10)>COUNTIF(Operational_RawData!$A:$A,"1_Operational"),"",INDEX(Operational_RawData!I:I,MATCH("1_Operational",Operational_RawData!$A:$A,0)+ROWS($2:10)-1)) -> 255.4 | J10: =IF(ROWS($2:10)>COUNTIF(Operational_RawData!$A:$A,"1_Operational"),"",INDEX(Operational_RawData!J:J,MATCH("1_Operational",Operational_RawData!$A:$A,0)+ROWS($2:10)-1)) -> 345.36 | K10: =IF(ROWS($2:10)>COUNTIF(Operational_RawData!$A:$A,"1_Operational"),"",INDEX(Operational_RawData!K:K,MATCH("1_Operational",Operational_RawData!$A:$A,0)+ROWS($2:10)-1)) -> 345.36 | L10: =IF(ROWS($2:10)>COUNTIF(Operational_RawData!$A:$A,"1_Operational"),"",INDEX(Operational_RawData!L:L,MATCH("1_Operational",Operational_RawData!$A:$A,0)+ROWS($2:10)-1)) -> 345.36 | M10: =IF(ROWS($2:10)>COUNTIF(Operational_RawData!$A:$A,"1_Operational"),"",INDEX(Operational_RawData!M:M,MATCH("1_Operational",Operational_RawData!$A:$A,0)+ROWS($2:10)-1)) -> 345.36 | N10: =IF(ROWS($2:10)>COUNTIF(Operational_RawData!$A:$A,"1_Operational"),"",INDEX(Operational_RawData!N:N,MATCH("1_Operational",Operational_RawData!$A:$A,0)+ROWS($2:10)-1)) -> 0.07 | O10: =IF(ROWS($2:10)>COUNTIF(Operational_RawData!$A:$A,"1_Operational"),"",INDEX(Operational_RawData!O:O,MATCH("1_Operational",Operational_RawData!$A:$A,0)+ROWS($2:10)-1)) -> 0.19 | P10: =IF(ROWS($2:10)>COUNTIF(Operational_RawData!$A:$A,"1_Operational"),"",INDEX(Operational_RawData!P:P,MATCH("1_Operational",Operational_RawData!$A:$A,0)+ROWS($2:10)-1)) -> 0.06 | Q10: =IF(ROWS($2:10)>COUNTIF(Operational_RawData!$A:$A,"1_Operational"),"",INDEX(Operational_RawData!Q:Q,MATCH("1_Operational",Operational_RawData!$A:$A,0)+ROWS($2:10)-1)) -> 0.1 | R10: =IF(ROWS($2:10)>COUNTIF(Operational_RawData!$A:$A,"1_Operational"),"",INDEX(Operational_RawData!R:R,MATCH("1_Operational",Operational_RawData!$A:$A,0)+ROWS($2:10)-1)) -> Pass | S10: =IF(ROWS($2:10)>COUNTIF(Operational_RawData!$A:$A,"1_Operational"),"",INDEX(Operational_RawData!S:S,MATCH("1_Operational",Operational_RawData!$A:$A,0)+ROWS($2:10)-1)) -> 0 | T10: =IF(ROWS($2:10)>COUNTIF(Operational_RawData!$A:$A,"1_Operational"),"",INDEX(Operational_RawData!T:T,MATCH("1_Operational",Operational_RawData!$A:$A,0)+ROWS($2:10)-1)) -> 0
A11: =IF(ROWS($2:11)>COUNTIF(Operational_RawData!$A:$A,"1_Operational"),"",INDEX(Operational_RawData!A:A,MATCH("1_Operational",Operational_RawData!$A:$A,0)+ROWS($2:11)-1)) -> 1_Operational | B11: =IF(ROWS($2:11)>COUNTIF(Operational_RawData!$A:$A,"1_Operational"),"",INDEX(Operational_RawData!B:B,MATCH("1_Operational",Operational_RawData!$A:$A,0)+ROWS($2:11)-1)) -> 144451.84 | C11: =IF(ROWS($2:11)>COUNTIF(Operational_RawData!$A:$A,"1_Operational"),"",INDEX(Operational_RawData!C:C,MATCH("1_Operational",Operational_RawData!$A:$A,0)+ROWS($2:11)-1)) -> 6.87 | D11: =IF(ROWS($2:11)>COUNTIF(Operational_RawData!$A:$A,"1_Operational"),"",INDEX(Operational_RawData!D:D,MATCH("1_Operational",Operational_RawData!$A:$A,0)+ROWS($2:11)-1)) -> 1307.768 | E11: =IF(ROWS($2:11)>COUNTIF(Operational_RawData!$A:$A,"1_Operational"),"",INDEX(Operational_RawData!E:E,MATCH("1_Operational",Operational_RawData!$A:$A,0)+ROWS($2:11)-1)) -> 3.58 | F11: =IF(ROWS($2:11)>COUNTIF(Operational_RawData!$A:$A,"1_Operational"),"",INDEX(Operational_RawData!F:F,MATCH("1_Operational",Operational_RawData!$A:$A,0)+ROWS($2:11)-1)) -> 253.48 | G11: =IF(ROWS($2:11)>COUNTIF(Operational_RawData!$A:$A,"1_Operational"),"",INDEX(Operational_RawData!G:G,MATCH("1_Operational",Operational_RawData!$A:$A,0)+ROWS($2:11)-1)) -> 253.48 | H11: =IF(ROWS($2:11)>COUNTIF(Operational_RawData!$A:$A,"1_Operational"),"",INDEX(Operational_RawData!H:H,MATCH("1_Operational",Operational_RawData!$A:$A,0)+ROWS($2:11)-1)) -> 253.48 | I11: =IF(ROWS($2:11)>COUNTIF(Operational_RawData!$A:$A,"1_Operational"),"",INDEX(Operational_RawData!I:I,MATCH("1_Operational",Operational_RawData!$A:$A,0)+ROWS($2:11)-1)) -> 253.48 | J11: =IF(ROWS($2:11)>COUNTIF(Operational_RawData!$A:$A,"1_Operational"),"",INDEX(Operational_RawData!J:J,MATCH("1_Operational",Operational_RawData!$A:$A,0)+ROWS($2:11)-1)) -> 344.08 | K11: =IF(ROWS($2:11)>COUNTIF(Operational_RawData!$A:$A,"1_Operational"),"",INDEX(Operational_RawData!K:K,MATCH("1_Operational",Operational_RawData!$A:$A,0)+ROWS($2:11)-1)) -> 344.08 | L11: =IF(ROWS($2:11)>COUNTIF(Operational_RawData!$A:$A,"1_Operational"),"",INDEX(Operational_RawData!L:L,MATCH("1_Operational",Operational_RawData!$A:$A,0)+ROWS($2:11)-1)) -> 344.08 | M11: =IF(ROWS($2:11)>COUNTIF(Operational_RawData!$A:$A,"1_Operational"),"",INDEX(Operational_RawData!M:M,MATCH("1_Operational",Operational_RawData!$A:$A,0)+ROWS($2:11)-1)) -> 344.08 | N11: =IF(ROWS($2:11)>COUNTIF(Operational_RawData!$A:$A,"1_Operational"),"",INDEX(Operational_RawData!N:N,MATCH("1_Operational",Operational_RawData!$A:$A,0)+ROWS($2:11)-1)) -> 0.07 | O11: =IF(ROWS($2:11)>COUNTIF(Operational_RawData!$A:$A,"1_Operational"),"",INDEX(Operational_RawData!O:O,MATCH("1_Operational",Operational_RawData!$A:$A,0)+ROWS($2:11)-1)) -> 0.19 | P11: =IF(ROWS($2:11)>COUNTIF(Operational_RawData!$A:$A,"1_Operational"),"",INDEX(Operational_RawData!P:P,MATCH("1_Operational",Operational_RawData!$A:$A,0)+ROWS($2:11)-1)) -> 0.06 | Q11: =IF(ROWS($2:11)>COUNTIF(Operational_RawData!$A:$A,"1_Operational"),"",INDEX(Operational_RawData!Q:Q,MATCH("1_Operational",Operational_RawData!$A:$A,0)+ROWS($2:11)-1)) -> 0.1 | R11: =IF(ROWS($2:11)>COUNTIF(Operational_RawData!$A:$A,"1_Operational"),"",INDEX(Operational_RawData!R:R,MATCH("1_Operational",Operational_RawData!$A:$A,0)+ROWS($2:11)-1)) -> Pass | S11: =IF(ROWS($2:11)>COUNTIF(Operational_RawData!$A:$A,"1_Operational"),"",INDEX(Operational_RawData!S:S,MATCH("1_Operational",Operational_RawData!$A:$A,0)+ROWS($2:11)-1)) -> 0 | T11: =IF(ROWS($2:11)>COUNTIF(Operational_RawData!$A:$A,"1_Operational"),"",INDEX(Operational_RawData!T:T,MATCH("1_Operational",Operational_RawData!$A:$A,0)+ROWS($2:11)-1)) -> 0
A12: =IF(ROWS($2:12)>COUNTIF(Operational_RawData!$A:$A,"1_Operational"),"",INDEX(Operational_RawData!A:A,MATCH("1_Operational",Operational_RawData!$A:$A,0)+ROWS($2:12)-1)) -> 1_Operational | B12: =IF(ROWS($2:12)>COUNTIF(Operational_RawData!$A:$A,"1_Operational"),"",INDEX(Operational_RawData!B:B,MATCH("1_Operational",Operational_RawData!$A:$A,0)+ROWS($2:12)-1)) -> 144456.84 | C12: =IF(ROWS($2:12)>COUNTIF(Operational_RawData!$A:$A,"1_Operational"),"",INDEX(Operational_RawData!C:C,MATCH("1_Operational",Operational_RawData!$A:$A,0)+ROWS($2:12)-1)) -> 7.63 | D12: =IF(ROWS($2:12)>COUNTIF(Operational_RawData!$A:$A,"1_Operational"),"",INDEX(Operational_RawData!D:D,MATCH("1_Operational",Operational_RawData!$A:$A,0)+ROWS($2:12)-1)) -> 1307.816 | E12: =IF(ROWS($2:12)>COUNTIF(Operational_RawData!$A:$A,"1_Operational"),"",INDEX(Operational_RawData!E:E,MATCH("1_Operational",Operational_RawData!$A:$A,0)+ROWS($2:12)-1)) -> 3.65 | F12: =IF(ROWS($2:12)>COUNTIF(Operational_RawData!$A:$A,"1_Operational"),"",INDEX(Operational_RawData!F:F,MATCH("1_Operational",Operational_RawData!$A:$A,0)+ROWS($2:12)-1)) -> 251.36 | G12: =IF(ROWS($2:12)>COUNTIF(Operational_RawData!$A:$A,"1_Operational"),"",INDEX(Operational_RawData!G:G,MATCH("1_Operational",Operational_RawData!$A:$A,0)+ROWS($2:12)-1)) -> 251.36 | H12: =IF(ROWS($2:12)>COUNTIF(Operational_RawData!$A:$A,"1_Operational"),"",INDEX(Operational_RawData!H:H,MATCH("1_Operational",Operational_RawData!$A:$A,0)+ROWS($2:12)-1)) -> 251.36 | I12: =IF(ROWS($2:12)>COUNTIF(Operational_RawData!$A:$A,"1_Operational"),"",INDEX(Operational_RawData!I:I,MATCH("1_Operational",Operational_RawData!$A:$A,0)+ROWS($2:12)-1)) -> 251.36 | J12: =IF(ROWS($2:12)>COUNTIF(Operational_RawData!$A:$A,"1_Operational"),"",INDEX(Operational_RawData!J:J,MATCH("1_Operational",Operational_RawData!$A:$A,0)+ROWS($2:12)-1)) -> 342.72 | K12: =IF(ROWS($2:12)>COUNTIF(Operational_RawData!$A:$A,"1_Operational"),"",INDEX(Operational_RawData!K:K,MATCH("1_Operational",Operational_RawData!$A:$A,0)+ROWS($2:12)-1)) -> 342.72 | L12: =IF(ROWS($2:12)>COUNTIF(Operational_RawData!$A:$A,"1_Operational"),"",INDEX(Operational_RawData!L:L,MATCH("1_Operational",Operational_RawData!$A:$A,0)+ROWS($2:12)-1)) -> 342.72 | M12: =IF(ROWS($2:12)>COUNTIF(Operational_RawData!$A:$A,"1_Operational"),"",INDEX(Operational_RawData!M:M,MATCH("1_Operational",Operational_RawData!$A:$A,0)+ROWS($2:12)-1)) -> 342.72 | N12: =IF(ROWS($2:12)>COUNTIF(Operational_RawData!$A:$A,"1_Operational"),"",INDEX(Operational_RawData!N:N,MATCH("1_Operational",Operational_RawData!$A:$A,0)+ROWS($2:12)-1)) -> 0.06 | O12: =IF(ROWS($2:12)>COUNTIF(Operational_RawData!$A:$A,"1_Operational"),"",INDEX(Operational_RawData!O:O,MATCH("1_Operational",Operational_RawData!$A:$A,0)+ROWS($2:12)-1)) -> 0.19 | P12: =IF(ROWS($2:12)>COUNTIF(Operational_RawData!$A:$A,"1_Operational"),"",INDEX(Operational_RawData!P:P,MATCH("1_Operational",Operational_RawData!$A:$A,0)+ROWS($2:12)-1)) -> 0.06 | Q12: =IF(ROWS($2:12)>COUNTIF(Operational_RawData!$A:$A,"1_Operational"),"",INDEX(Operational_RawData!Q:Q,MATCH("1_Operational",Operational_RawData!$A:$A,0)+ROWS($2:12)-1)) -> 0.1 | R12: =IF(ROWS($2:12)>COUNTIF(Operational_RawData!$A:$A,"1_Operational"),"",INDEX(Operational_RawData!R:R,MATCH("1_Operational",Operational_RawData!$A:$A,0)+ROWS($2:12)-1)) -> Pass | S12: =IF(ROWS($2:12)>COUNTIF(Operational_RawData!$A:$A,"1_Operational"),"",INDEX(Operational_RawData!S:S,MATCH("1_Operational",Operational_RawData!$A:$A,0)+ROWS($2:12)-1)) -> 0 | T12: =IF(ROWS($2:12)>COUNTIF(Operational_RawData!$A:$A,"1_Operational"),"",INDEX(Operational_RawData!T:T,MATCH("1_Operational",Operational_RawData!$A:$A,0)+ROWS($2:12)-1)) -> 0
A13: =IF(ROWS($2:13)>COUNTIF(Operational_RawData!$A:$A,"1_Operational"),"",INDEX(Operational_RawData!A:A,MATCH("1_Operational",Operational_RawData!$A:$A,0)+ROWS($2:13)-1)) -> 1_Operational | B13: =IF(ROWS($2:13)>COUNTIF(Operational_RawData!$A:$A,"1_Operational"),"",INDEX(Operational_RawData!B:B,MATCH("1_Operational",Operational_RawData!$A:$A,0)+ROWS($2:13)-1)) -> 144501.84 | C13: =IF(ROWS($2:13)>COUNTIF(Operational_RawData!$A:$A,"1_Operational"),"",INDEX(Operational_RawData!C:C,MATCH("1_Operational",Operational_RawData!$A:$A,0)+ROWS($2:13)-1)) -> 8.36 | D13: =IF(ROWS($2:13)>COUNTIF(Operational_RawData!$A:$A,"1_Operational"),"",INDEX(Operational_RawData!D:D,MATCH("1_Operational",Operational_RawData!$A:$A,0)+ROWS($2:13)-1)) -> 1307.873 | E13: =IF(ROWS($2:13)>COUNTIF(Operational_RawData!$A:$A,"1_Operational"),"",INDEX(Operational_RawData!E:E,MATCH("1_Operational",Operational_RawData!$A:$A,0)+ROWS($2:13)-1)) -> 3.64 | F13: =IF(ROWS($2:13)>COUNTIF(Operational_RawData!$A:$A,"1_Operational"),"",INDEX(Operational_RawData!F:F,MATCH("1_Operational",Operational_RawData!$A:$A,0)+ROWS($2:13)-1)) -> 249.72 | G13: =IF(ROWS($2:13)>COUNTIF(Operational_RawData!$A:$A,"1_Operational"),"",INDEX(Operational_RawData!G:G,MATCH("1_Operational",Operational_RawData!$A:$A,0)+ROWS($2:13)-1)) -> 249.72 | H13: =IF(ROWS($2:13)>COUNTIF(Operational_RawData!$A:$A,"1_Operational"),"",INDEX(Operational_RawData!H:H,MATCH("1_Operational",Operational_RawData!$A:$A,0)+ROWS($2:13)-1)) -> 249.72 | I13: =IF(ROWS($2:13)>COUNTIF(Operational_RawData!$A:$A,"1_Operational"),"",INDEX(Operational_RawData!I:I,MATCH("1_Operational",Operational_RawData!$A:$A,0)+ROWS($2:13)-1)) -> 249.72 | J13: =IF(ROWS($2:13)>COUNTIF(Operational_RawData!$A:$A,"1_Operational"),"",INDEX(Operational_RawData!J:J,MATCH("1_Operational",Operational_RawData!$A:$A,0)+ROWS($2:13)-1)) -> 341.36 | K13: =IF(ROWS($2:13)>COUNTIF(Operational_RawData!$A:$A,"1_Operational"),"",INDEX(Operational_RawData!K:K,MATCH("1_Operational",Operational_RawData!$A:$A,0)+ROWS($2:13)-1)) -> 341.36 | L13: =IF(ROWS($2:13)>COUNTIF(Operational_RawData!$A:$A,"1_Operational"),"",INDEX(Operational_RawData!L:L,MATCH("1_Operational",Operational_RawData!$A:$A,0)+ROWS($2:13)-1)) -> 341.36 | M13: =IF(ROWS($2:13)>COUNTIF(Operational_RawData!$A:$A,"1_Operational"),"",INDEX(Operational_RawData!M:M,MATCH("1_Operational",Operational_RawData!$A:$A,0)+ROWS($2:13)-1)) -> 341.36 | N13: =IF(ROWS($2:13)>COUNTIF(Operational_RawData!$A:$A,"1_Operational"),"",INDEX(Operational_RawData!N:N,MATCH("1_Operational",Operational_RawData!$A:$A,0)+ROWS($2:13)-1)) -> 0.08 | O13: =IF(ROWS($2:13)>COUNTIF(Operational_RawData!$A:$A,"1_Operational"),"",INDEX(Operational_RawData!O:O,MATCH("1_Operational",Operational_RawData!$A:$A,0)+ROWS($2:13)-1)) -> 0.19 | P13: =IF(ROWS($2:13)>COUNTIF(Operational_RawData!$A:$A,"1_Operational"),"",INDEX(Operational_RawData!P:P,MATCH("1_Operational",Operational_RawData!$A:$A,0)+ROWS($2:13)-1)) -> 0.06 | Q13: =IF(ROWS($2:13)>COUNTIF(Operational_RawData!$A:$A,"1_Operational"),"",INDEX(Operational_RawData!Q:Q,MATCH("1_Operational",Operational_RawData!$A:$A,0)+ROWS($2:13)-1)) -> 0.1 | R13: =IF(ROWS($2:13)>COUNTIF(Operational_RawData!$A:$A,"1_Operational"),"",INDEX(Operational_RawData!R:R,MATCH("1_Operational",Operational_RawData!$A:$A,0)+ROWS($2:13)-1)) -> Pass | S13: =IF(ROWS($2:13)>COUNTIF(Operational_RawData!$A:$A,"1_Operational"),"",INDEX(Operational_RawData!S:S,MATCH("1_Operational",Operational_RawData!$A:$A,0)+ROWS($2:13)-1)) -> 0 | T13: =IF(ROWS($2:13)>COUNTIF(Operational_RawData!$A:$A,"1_Operational"),"",INDEX(Operational_RawData!T:T,MATCH("1_Operational",Operational_RawData!$A:$A,0)+ROWS($2:13)-1)) -> 0
A14: =IF(ROWS($2:14)>COUNTIF(Operational_RawData!$A:$A,"1_Operational"),"",INDEX(Operational_RawData!A:A,MATCH("1_Operational",Operational_RawData!$A:$A,0)+ROWS($2:14)-1)) -> 1_Operational | B14: =IF(ROWS($2:14)>COUNTIF(Operational_RawData!$A:$A,"1_Operational"),"",INDEX(Operational_RawData!B:B,MATCH("1_Operational",Operational_RawData!$A:$A,0)+ROWS($2:14)-1)) -> 144506.85 | C14: =IF(ROWS($2:14)>COUNTIF(Operational_RawData!$A:$A,"1_Operational"),"",INDEX(Operational_RawData!C:C,MATCH("1_Operational",Operational_RawData!$A:$A,0)+ROWS($2:14)-1)) -> 9.12 | D14: =IF(ROWS($2:14)>COUNTIF(Operational_RawData!$A:$A,"1_Operational"),"",INDEX(Operational_RawData!D:D,MATCH("1_Operational",Operational_RawData!$A:$A,0)+ROWS($2:14)-1)) -> 1307.934 | E14: =IF(ROWS($2:14)>COUNTIF(Operational_RawData!$A:$A,"1_Operational"),"",INDEX(Operational_RawData!E:E,MATCH("1_Operational",Operational_RawData!$A:$A,0)+ROWS($2:14)-1)) -> 3.61 | F14: =IF(ROWS($2:14)>COUNTIF(Operational_RawData!$A:$A,"1_Operational"),"",INDEX(Operational_RawData!F:F,MATCH("1_Operational",Operational_RawData!$A:$A,0)+ROWS($2:14)-1)) -> 247.68 | G14: =IF(ROWS($2:14)>COUNTIF(Operational_RawData!$A:$A,"1_Operational"),"",INDEX(Operational_RawData!G:G,MATCH("1_Operational",Operational_RawData!$A:$A,0)+ROWS($2:14)-1)) -> 247.68 | H14: =IF(ROWS($2:14)>COUNTIF(Operational_RawData!$A:$A,"1_Operational"),"",INDEX(Operational_RawData!H:H,MATCH("1_Operational",Operational_RawData!$A:$A,0)+ROWS($2:14)-1)) -> 247.68 | I14: =IF(ROWS($2:14)>COUNTIF(Operational_RawData!$A:$A,"1_Operational"),"",INDEX(Operational_RawData!I:I,MATCH("1_Operational",Operational_RawData!$A:$A,0)+ROWS($2:14)-1)) -> 247.68 | J14: =IF(ROWS($2:14)>COUNTIF(Operational_RawData!$A:$A,"1_Operational"),"",INDEX(Operational_RawData!J:J,MATCH("1_Operational",Operational_RawData!$A:$A,0)+ROWS($2:14)-1)) -> 339.88 | K14: =IF(ROWS($2:14)>COUNTIF(Operational_RawData!$A:$A,"1_Operational"),"",INDEX(Operational_RawData!K:K,MATCH("1_Operational",Operational_RawData!$A:$A,0)+ROWS($2:14)-1)) -> 339.88 | L14: =IF(ROWS($2:14)>COUNTIF(Operational_RawData!$A:$A,"1_Operational"),"",INDEX(Operational_RawData!L:L,MATCH("1_Operational",Operational_RawData!$A:$A,0)+ROWS($2:14)-1)) -> 339.88 | M14: =IF(ROWS($2:14)>COUNTIF(Operational_RawData!$A:$A,"1_Operational"),"",INDEX(Operational_RawData!M:M,MATCH("1_Operational",Operational_RawData!$A:$A,0)+ROWS($2:14)-1)) -> 339.88 | N14: =IF(ROWS($2:14)>COUNTIF(Operational_RawData!$A:$A,"1_Operational"),"",INDEX(Operational_RawData!N:N,MATCH("1_Operational",Operational_RawData!$A:$A,0)+ROWS($2:14)-1)) -> 0.08 | O14: =IF(ROWS($2:14)>COUNTIF(Operational_RawData!$A:$A,"1_Operational"),"",INDEX(Operational_RawData!O:O,MATCH("1_Operational",Operational_RawData!$A:$A,0)+ROWS($2:14)-1)) -> 0.19 | P14: =IF(ROWS($2:14)>COUNTIF(Operational_RawData!$A:$A,"1_Operational"),"",INDEX(Operational_RawData!P:P,MATCH("1_Operational",Operational_RawData!$A:$A,0)+ROWS($2:14)-1)) -> 0.06 | Q14: =IF(ROWS($2:14)>COUNTIF(Operational_RawData!$A:$A,"1_Operational"),"",INDEX(Operational_RawData!Q:Q,MATCH("1_Operational",Operational_RawData!$A:$A,0)+ROWS($2:14)-1)) -> 0.1 | R14: =IF(ROWS($2:14)>COUNTIF(Operational_RawData!$A:$A,"1_Operational"),"",INDEX(Operational_RawData!R:R,MATCH("1_Operational",Operational_RawData!$A:$A,0)+ROWS($2:14)-1)) -> Pass | S14: =IF(ROWS($2:14)>COUNTIF(Operational_RawData!$A:$A,"1_Operational"),"",INDEX(Operational_RawData!S:S,MATCH("1_Operational",Operational_RawData!$A:$A,0)+ROWS($2:14)-1)) -> 0 | T14: =IF(ROWS($2:14)>COUNTIF(Operational_RawData!$A:$A,"1_Operational"),"",INDEX(Operational_RawData!T:T,MATCH("1_Operational",Operational_RawData!$A:$A,0)+ROWS($2:14)-1)) -> 0
